<?xml version="1.0" encoding="UTF-8"?>
<!-- Generated by org.testng.reporters.JUnitReportReporter -->
<testsuite skipped="0" hostname="DESKTOP-FFRREGV" name="com.bridgelabz.test.UserTest" tests="7" failures="3" timestamp="2020-05-15T18:29:55 BST" time="913.612" errors="0">
  <testcase name="updatePassword" time="92.234" classname="com.bridgelabz.test.UserTest">
    <failure type="java.lang.AssertionError" message="expected [http://localhost:4200/login] but found [http://localhost:4200/resetPassword/eyJhbGciOiJIUzUxMiJ9.eyJzdWIiOiIyNCJ9.SsxOKrdA-pkgRPoKphDdd2M2kLmkw0bURdtKu8yc4bD-ivlbqJXtsKqpj1q7HSNb8w-vTsTcP9LQH58dalnZ3Q]">
      <![CDATA[java.lang.AssertionError: expected [http://localhost:4200/login] but found [http://localhost:4200/resetPassword/eyJhbGciOiJIUzUxMiJ9.eyJzdWIiOiIyNCJ9.SsxOKrdA-pkgRPoKphDdd2M2kLmkw0bURdtKu8yc4bD-ivlbqJXtsKqpj1q7HSNb8w-vTsTcP9LQH58dalnZ3Q]
at org.testng.Assert.fail(Assert.java:97)
at org.testng.Assert.assertEqualsImpl(Assert.java:136)
at org.testng.Assert.assertEquals(Assert.java:118)
at org.testng.Assert.assertEquals(Assert.java:575)
at org.testng.Assert.assertEquals(Assert.java:585)
at com.bridgelabz.test.UserTest.updatePassword(UserTest.java:138)
at sun.reflect.NativeMethodAccessorImpl.invoke0(Native Method)
at sun.reflect.NativeMethodAccessorImpl.invoke(Unknown Source)
at sun.reflect.DelegatingMethodAccessorImpl.invoke(Unknown Source)
at java.lang.reflect.Method.invoke(Unknown Source)
at org.testng.internal.MethodInvocationHelper.invokeMethod(MethodInvocationHelper.java:135)
at org.testng.internal.TestInvoker.invokeMethod(TestInvoker.java:598)
at org.testng.internal.TestInvoker.invokeTestMethod(TestInvoker.java:174)
at org.testng.internal.MethodRunner.runInSequence(MethodRunner.java:46)
at org.testng.internal.TestInvoker$MethodInvocationAgent.invoke(TestInvoker.java:821)
at org.testng.internal.TestInvoker.invokeTestMethods(TestInvoker.java:147)
at org.testng.internal.TestMethodWorker.invokeTestMethods(TestMethodWorker.java:146)
at org.testng.internal.TestMethodWorker.run(TestMethodWorker.java:128)
at java.util.ArrayList.forEach(Unknown Source)
at org.testng.TestRunner.privateRun(TestRunner.java:767)
at org.testng.TestRunner.run(TestRunner.java:588)
at org.testng.SuiteRunner.runTest(SuiteRunner.java:384)
at org.testng.SuiteRunner.runSequentially(SuiteRunner.java:378)
at org.testng.SuiteRunner.privateRun(SuiteRunner.java:337)
at org.testng.SuiteRunner.run(SuiteRunner.java:286)
at org.testng.SuiteRunnerWorker.runSuite(SuiteRunnerWorker.java:53)
at org.testng.SuiteRunnerWorker.run(SuiteRunnerWorker.java:96)
at org.testng.TestNG.runSuitesSequentially(TestNG.java:1214)
at org.testng.TestNG.runSuitesLocally(TestNG.java:1136)
at org.testng.TestNG.runSuites(TestNG.java:1066)
at org.testng.TestNG.run(TestNG.java:1034)
at org.testng.remote.AbstractRemoteTestNG.run(AbstractRemoteTestNG.java:115)
at org.testng.remote.RemoteTestNG.initAndRun(RemoteTestNG.java:251)
at org.testng.remote.RemoteTestNG.main(RemoteTestNG.java:77)
]]>
    </failure>
  </testcase> <!-- updatePassword -->
  <system-out/>
  <testcase name="loginPage" time="142.189" classname="com.bridgelabz.test.UserTest"/>
  <system-out/>
  <testcase name="updatePassword" time="91.923" classname="com.bridgelabz.test.UserTest"/>
  <system-out/>
  <testcase name="registrationPage" time="184.587" classname="com.bridgelabz.test.UserTest">
    <failure type="java.lang.AssertionError" message="expected [http://localhost:4200/login] but found [http://localhost:4200/registration]">
      <![CDATA[java.lang.AssertionError: expected [http://localhost:4200/login] but found [http://localhost:4200/registration]
at org.testng.Assert.fail(Assert.java:97)
at org.testng.Assert.assertEqualsImpl(Assert.java:136)
at org.testng.Assert.assertEquals(Assert.java:118)
at org.testng.Assert.assertEquals(Assert.java:575)
at org.testng.Assert.assertEquals(Assert.java:585)
at com.bridgelabz.test.UserTest.registrationPage(UserTest.java:69)
at sun.reflect.NativeMethodAccessorImpl.invoke0(Native Method)
at sun.reflect.NativeMethodAccessorImpl.invoke(Unknown Source)
at sun.reflect.DelegatingMethodAccessorImpl.invoke(Unknown Source)
at java.lang.reflect.Method.invoke(Unknown Source)
at org.testng.internal.MethodInvocationHelper.invokeMethod(MethodInvocationHelper.java:135)
at org.testng.internal.TestInvoker.invokeMethod(TestInvoker.java:598)
at org.testng.internal.TestInvoker.invokeTestMethod(TestInvoker.java:174)
at org.testng.internal.MethodRunner.runInSequence(MethodRunner.java:46)
at org.testng.internal.TestInvoker$MethodInvocationAgent.invoke(TestInvoker.java:821)
at org.testng.internal.TestInvoker.invokeTestMethods(TestInvoker.java:147)
at org.testng.internal.TestMethodWorker.invokeTestMethods(TestMethodWorker.java:146)
at org.testng.internal.TestMethodWorker.run(TestMethodWorker.java:128)
at java.util.ArrayList.forEach(Unknown Source)
at org.testng.TestRunner.privateRun(TestRunner.java:767)
at org.testng.TestRunner.run(TestRunner.java:588)
at org.testng.SuiteRunner.runTest(SuiteRunner.java:384)
at org.testng.SuiteRunner.runSequentially(SuiteRunner.java:378)
at org.testng.SuiteRunner.privateRun(SuiteRunner.java:337)
at org.testng.SuiteRunner.run(SuiteRunner.java:286)
at org.testng.SuiteRunnerWorker.runSuite(SuiteRunnerWorker.java:53)
at org.testng.SuiteRunnerWorker.run(SuiteRunnerWorker.java:96)
at org.testng.TestNG.runSuitesSequentially(TestNG.java:1214)
at org.testng.TestNG.runSuitesLocally(TestNG.java:1136)
at org.testng.TestNG.runSuites(TestNG.java:1066)
at org.testng.TestNG.run(TestNG.java:1034)
at org.testng.remote.AbstractRemoteTestNG.run(AbstractRemoteTestNG.java:115)
at org.testng.remote.RemoteTestNG.initAndRun(RemoteTestNG.java:251)
at org.testng.remote.RemoteTestNG.main(RemoteTestNG.java:77)
]]>
    </failure>
  </testcase> <!-- registrationPage -->
  <system-out/>
  <testcase name="registrationPage" time="185.744" classname="com.bridgelabz.test.UserTest"/>
  <system-out/>
  <testcase name="forgotAccount" time="83.183" classname="com.bridgelabz.test.UserTest"/>
  <system-out/>
  <testcase name="loginPage" time="133.752" classname="com.bridgelabz.test.UserTest">
    <failure type="java.lang.AssertionError" message="expected [http://localhost:4200/dashboard] but found [http://localhost:4200/login]">
      <![CDATA[java.lang.AssertionError: expected [http://localhost:4200/dashboard] but found [http://localhost:4200/login]
at org.testng.Assert.fail(Assert.java:97)
at org.testng.Assert.assertEqualsImpl(Assert.java:136)
at org.testng.Assert.assertEquals(Assert.java:118)
at org.testng.Assert.assertEquals(Assert.java:575)
at org.testng.Assert.assertEquals(Assert.java:585)
at com.bridgelabz.test.UserTest.loginPage(UserTest.java:90)
at sun.reflect.NativeMethodAccessorImpl.invoke0(Native Method)
at sun.reflect.NativeMethodAccessorImpl.invoke(Unknown Source)
at sun.reflect.DelegatingMethodAccessorImpl.invoke(Unknown Source)
at java.lang.reflect.Method.invoke(Unknown Source)
at org.testng.internal.MethodInvocationHelper.invokeMethod(MethodInvocationHelper.java:135)
at org.testng.internal.TestInvoker.invokeMethod(TestInvoker.java:598)
at org.testng.internal.TestInvoker.invokeTestMethod(TestInvoker.java:174)
at org.testng.internal.MethodRunner.runInSequence(MethodRunner.java:46)
at org.testng.internal.TestInvoker$MethodInvocationAgent.invoke(TestInvoker.java:821)
at org.testng.internal.TestInvoker.invokeTestMethods(TestInvoker.java:147)
at org.testng.internal.TestMethodWorker.invokeTestMethods(TestMethodWorker.java:146)
at org.testng.internal.TestMethodWorker.run(TestMethodWorker.java:128)
at java.util.ArrayList.forEach(Unknown Source)
at org.testng.TestRunner.privateRun(TestRunner.java:767)
at org.testng.TestRunner.run(TestRunner.java:588)
at org.testng.SuiteRunner.runTest(SuiteRunner.java:384)
at org.testng.SuiteRunner.runSequentially(SuiteRunner.java:378)
at org.testng.SuiteRunner.privateRun(SuiteRunner.java:337)
at org.testng.SuiteRunner.run(SuiteRunner.java:286)
at org.testng.SuiteRunnerWorker.runSuite(SuiteRunnerWorker.java:53)
at org.testng.SuiteRunnerWorker.run(SuiteRunnerWorker.java:96)
at org.testng.TestNG.runSuitesSequentially(TestNG.java:1214)
at org.testng.TestNG.runSuitesLocally(TestNG.java:1136)
at org.testng.TestNG.runSuites(TestNG.java:1066)
at org.testng.TestNG.run(TestNG.java:1034)
at org.testng.remote.AbstractRemoteTestNG.run(AbstractRemoteTestNG.java:115)
at org.testng.remote.RemoteTestNG.initAndRun(RemoteTestNG.java:251)
at org.testng.remote.RemoteTestNG.main(RemoteTestNG.java:77)
]]>
    </failure>
  </testcase> <!-- loginPage -->
  <system-out/>
</testsuite> <!-- com.bridgelabz.test.UserTest -->
